<mujoco>
    <!-- === Configuration parameter stuff, default values === -->
    <default>
        <default class="position">
            <position ctrllimited="true" forcelimited="false" />
        </default>
        <default class="geom0">
            <geom conaffinity="0" contype="1" friction="0 0.0 0.0" margin="0.001" rgba="0.75 0.6 0.5 1" solimp="0.95 0.95 0.01" solref="0.008 1" />
        </default>
        <default class="link">
            <joint armature="0.1" damping="5" limited="true" stiffness="0" />
        </default>
    </default>
    <!-- === Physical robot definitions === -->
    <worldbody>
        <body pos="0.00 -5.00 1.00" euler="90.00 0 0">
            <geom type="mesh" mesh="0_STLS_dir/CRL_Wing.stl" rgba="0.2 0.5 0.8 1" />
            <joint name="obstacle_custom_0_joint" type="free" damping="0.001" />
        </body>
        <light pos="0 0 10" dir="0 0 -1" castshadow="false" />
        <!--
		-->
    <geom type="plane" size="100 100 0.1" friction="0 0 0" rgba="0.984 0.984 0.984 1" />
        <body name="base" pos="-5.6000000000000005 0 0.05">
            <geom size="0.05" type="sphere" />
            <body name="base_link" pos="0.05 0 0">
                <geom class="geom0" fromto="0 0 0 0.1 0 0" size="0.035" type="capsule" />
                <joint axis="0 0 1" class="link" name="base_joint" pos="0 0 0" range="-40.5 40.5" type="hinge" />
                <body name="link_0" pos="0.1 0 0">
                    <geom fromto="0 0 0 0.1 0 0" size="0.035" type="capsule" rgba="0.274 0.274 0.274 1" friction="0 0 0" />
                    <joint axis="0 0 1" class="link" name="joint_0" pos="0 0 0" range="-40.5 40.5" type="hinge" stiffness="10" />
                    <body name="link_1" pos="0.1 0 0">
                        <geom fromto="0 0 0 0.1 0 0" size="0.035" type="capsule" rgba="0.196 0.196 0.196 1" friction="0 0 0" />
                        <joint axis="0 0 1" class="link" name="joint_1" pos="0 0 0" range="-40.5 40.5" type="hinge" stiffness="10" />
                        <body name="link_2" pos="0.1 0 0">
                            <geom fromto="0 0 0 0.1 0 0" size="0.035" type="capsule" rgba="0.274 0.274 0.274 1" friction="0 0 0" />
                            <joint axis="0 0 1" class="link" name="joint_2" pos="0 0 0" range="-40.5 40.5" type="hinge" stiffness="10" />
                            <body name="link_3" pos="0.1 0 0">
                                <geom fromto="0 0 0 0.1 0 0" size="0.035" type="capsule" rgba="0.196 0.196 0.196 1" friction="0 0 0" />
                                <joint axis="0 0 1" class="link" name="joint_3" pos="0 0 0" range="-40.5 40.5" type="hinge" stiffness="10" />
                                <body name="link_4" pos="0.1 0 0">
                                    <geom fromto="0 0 0 0.1 0 0" size="0.035" type="capsule" rgba="0.274 0.274 0.274 1" friction="0 0 0" />
                                    <joint axis="0 0 1" class="link" name="joint_4" pos="0 0 0" range="-40.5 40.5" type="hinge" stiffness="10" />
                                    <body name="link_5" pos="0.1 0 0">
                                        <geom fromto="0 0 0 0.1 0 0" size="0.035" type="capsule" rgba="0.196 0.196 0.196 1" friction="0 0 0" />
                                        <joint axis="0 0 1" class="link" name="joint_5" pos="0 0 0" range="-40.5 40.5" type="hinge" stiffness="10" />
                                        <body name="link_6" pos="0.1 0 0">
                                            <geom fromto="0 0 0 0.1 0 0" size="0.035" type="capsule" rgba="0.274 0.274 0.274 1" friction="0 0 0" />
                                            <joint axis="0 0 1" class="link" name="joint_6" pos="0 0 0" range="-40.5 40.5" type="hinge" stiffness="10" />
                                            <body name="link_7" pos="0.1 0 0">
                                                <geom fromto="0 0 0 0.1 0 0" size="0.035" type="capsule" rgba="0.196 0.196 0.196 1" friction="0 0 0" />
                                                <joint axis="0 0 1" class="link" name="joint_7" pos="0 0 0" range="-40.5 40.5" type="hinge" stiffness="10" />
                                                <body name="link_8" pos="0.1 0 0">
                                                    <geom fromto="0 0 0 0.1 0 0" size="0.035" type="capsule" rgba="0.274 0.274 0.274 1" friction="0 0 0" />
                                                    <joint axis="0 0 1" class="link" name="joint_8" pos="0 0 0" range="-40.5 40.5" type="hinge" stiffness="10" />
                                                    <body name="link_9" pos="0.1 0 0">
                                                        <geom fromto="0 0 0 0.1 0 0" size="0.035" type="capsule" rgba="0.196 0.196 0.196 1" friction="0 0 0" />
                                                        <joint axis="0 0 1" class="link" name="joint_9" pos="0 0 0" range="-40.5 40.5" type="hinge" stiffness="10" />
                                                        <body name="link_10" pos="0.1 0 0">
                                                            <geom fromto="0 0 0 0.1 0 0" size="0.035" type="capsule" rgba="0.274 0.274 0.274 1" friction="0 0 0" />
                                                            <joint axis="0 0 1" class="link" name="joint_10" pos="0 0 0" range="-40.5 40.5" type="hinge" stiffness="10" />
                                                            <body name="link_11" pos="0.1 0 0">
                                                                <geom fromto="0 0 0 0.1 0 0" size="0.035" type="capsule" rgba="0.196 0.196 0.196 1" friction="0 0 0" />
                                                                <joint axis="0 0 1" class="link" name="joint_11" pos="0 0 0" range="-40.5 40.5" type="hinge" stiffness="10" />
                                                                <body name="link_12" pos="0.1 0 0">
                                                                    <geom fromto="0 0 0 0.1 0 0" size="0.035" type="capsule" rgba="0.274 0.274 0.274 1" friction="0 0 0" />
                                                                    <joint axis="0 0 1" class="link" name="joint_12" pos="0 0 0" range="-40.5 40.5" type="hinge" stiffness="10" />
                                                                    <body name="link_13" pos="0.1 0 0">
                                                                        <geom fromto="0 0 0 0.1 0 0" size="0.035" type="capsule" rgba="0.196 0.196 0.196 1" friction="0 0 0" />
                                                                        <joint axis="0 0 1" class="link" name="joint_13" pos="0 0 0" range="-40.5 40.5" type="hinge" stiffness="10" />
                                                                        <body name="link_14" pos="0.1 0 0">
                                                                            <geom fromto="0 0 0 0.1 0 0" size="0.035" type="capsule" rgba="0.274 0.274 0.274 1" friction="0 0 0" />
                                                                            <joint axis="0 0 1" class="link" name="joint_14" pos="0 0 0" range="-40.5 40.5" type="hinge" stiffness="10" />
                                                                            <body name="link_15" pos="0.1 0 0">
                                                                                <geom fromto="0 0 0 0.1 0 0" size="0.035" type="capsule" rgba="0.196 0.196 0.196 1" friction="0 0 0" />
                                                                                <joint axis="0 0 1" class="link" name="joint_15" pos="0 0 0" range="-40.5 40.5" type="hinge" stiffness="10" />
                                                                                <body name="link_16" pos="0.1 0 0">
                                                                                    <geom fromto="0 0 0 0.1 0 0" size="0.035" type="capsule" rgba="0.274 0.274 0.274 1" friction="0 0 0" />
                                                                                    <joint axis="0 0 1" class="link" name="joint_16" pos="0 0 0" range="-40.5 40.5" type="hinge" stiffness="10" />
                                                                                    <body name="link_17" pos="0.1 0 0">
                                                                                        <geom fromto="0 0 0 0.1 0 0" size="0.035" type="capsule" rgba="0.196 0.196 0.196 1" friction="0 0 0" />
                                                                                        <joint axis="0 0 1" class="link" name="joint_17" pos="0 0 0" range="-40.5 40.5" type="hinge" stiffness="10" />
                                                                                        <body name="link_18" pos="0.1 0 0">
                                                                                            <geom fromto="0 0 0 0.1 0 0" size="0.035" type="capsule" rgba="0.274 0.274 0.274 1" friction="0 0 0" />
                                                                                            <joint axis="0 0 1" class="link" name="joint_18" pos="0 0 0" range="-40.5 40.5" type="hinge" stiffness="10" />
                                                                                            <body name="link_19" pos="0.1 0 0">
                                                                                                <geom fromto="0 0 0 0.1 0 0" size="0.035" type="capsule" rgba="0.196 0.196 0.196 1" friction="0 0 0" />
                                                                                                <joint axis="0 0 1" class="link" name="joint_19" pos="0 0 0" range="-40.5 40.5" type="hinge" stiffness="10" />
                                                                                                <body name="link_20" pos="0.1 0 0">
                                                                                                    <geom fromto="0 0 0 0.1 0 0" size="0.035" type="capsule" rgba="0.274 0.274 0.274 1" friction="0 0 0" />
                                                                                                    <joint axis="0 0 1" class="link" name="joint_20" pos="0 0 0" range="-40.5 40.5" type="hinge" stiffness="10" />
                                                                                                    <body name="link_21" pos="0.1 0 0">
                                                                                                        <geom fromto="0 0 0 0.1 0 0" size="0.035" type="capsule" rgba="0.196 0.196 0.196 1" friction="0 0 0" />
                                                                                                        <joint axis="0 0 1" class="link" name="joint_21" pos="0 0 0" range="-40.5 40.5" type="hinge" stiffness="10" />
                                                                                                        <body name="link_22" pos="0.1 0 0">
                                                                                                            <geom fromto="0 0 0 0.1 0 0" size="0.035" type="capsule" rgba="0.274 0.274 0.274 1" friction="0 0 0" />
                                                                                                            <joint axis="0 0 1" class="link" name="joint_22" pos="0 0 0" range="-40.5 40.5" type="hinge" stiffness="10" />
                                                                                                            <body name="link_23" pos="0.1 0 0">
                                                                                                                <geom fromto="0 0 0 0.1 0 0" size="0.035" type="capsule" rgba="0.196 0.196 0.196 1" friction="0 0 0" />
                                                                                                                <joint axis="0 0 1" class="link" name="joint_23" pos="0 0 0" range="-40.5 40.5" type="hinge" stiffness="10" />
                                                                                                                <body name="link_24" pos="0.1 0 0">
                                                                                                                    <geom fromto="0 0 0 0.1 0 0" size="0.035" type="capsule" rgba="0.274 0.274 0.274 1" friction="0 0 0" />
                                                                                                                    <joint axis="0 0 1" class="link" name="joint_24" pos="0 0 0" range="-40.5 40.5" type="hinge" stiffness="10" />
                                                                                                                    <body name="link_25" pos="0.1 0 0">
                                                                                                                        <geom fromto="0 0 0 0.1 0 0" size="0.035" type="capsule" rgba="0.196 0.196 0.196 1" friction="0 0 0" />
                                                                                                                        <joint axis="0 0 1" class="link" name="joint_25" pos="0 0 0" range="-40.5 40.5" type="hinge" stiffness="10" />
                                                                                                                        <body name="link_26" pos="0.1 0 0">
                                                                                                                            <geom fromto="0 0 0 0.1 0 0" size="0.035" type="capsule" rgba="0.274 0.274 0.274 1" friction="0 0 0" />
                                                                                                                            <joint axis="0 0 1" class="link" name="joint_26" pos="0 0 0" range="-40.5 40.5" type="hinge" stiffness="10" />
                                                                                                                            <body name="link_27" pos="0.1 0 0">
                                                                                                                                <geom fromto="0 0 0 0.1 0 0" size="0.035" type="capsule" rgba="0.196 0.196 0.196 1" friction="0 0 0" />
                                                                                                                                <joint axis="0 0 1" class="link" name="joint_27" pos="0 0 0" range="-40.5 40.5" type="hinge" stiffness="10" />
                                                                                                                                <body name="link_28" pos="0.1 0 0">
                                                                                                                                    <geom fromto="0 0 0 0.1 0 0" size="0.035" type="capsule" rgba="0.274 0.274 0.274 1" friction="0 0 0" />
                                                                                                                                    <joint axis="0 0 1" class="link" name="joint_28" pos="0 0 0" range="-40.5 40.5" type="hinge" stiffness="10" />
                                                                                                                                    <body name="link_29" pos="0.1 0 0">
                                                                                                                                        <geom fromto="0 0 0 0.1 0 0" size="0.035" type="capsule" rgba="0.196 0.196 0.196 1" friction="0 0 0" />
                                                                                                                                        <joint axis="0 0 1" class="link" name="joint_29" pos="0 0 0" range="-40.5 40.5" type="hinge" stiffness="10" />
                                                                                                                                        <body name="link_30" pos="0.1 0 0">
                                                                                                                                            <geom fromto="0 0 0 0.1 0 0" size="0.035" type="capsule" rgba="0.274 0.274 0.274 1" friction="0 0 0" />
                                                                                                                                            <joint axis="0 0 1" class="link" name="joint_30" pos="0 0 0" range="-40.5 40.5" type="hinge" stiffness="10" />
                                                                                                                                            <body name="link_31" pos="0.1 0 0">
                                                                                                                                                <geom fromto="0 0 0 0.1 0 0" size="0.035" type="capsule" rgba="0.196 0.196 0.196 1" friction="0 0 0" />
                                                                                                                                                <joint axis="0 0 1" class="link" name="joint_31" pos="0 0 0" range="-40.5 40.5" type="hinge" stiffness="10" />
                                                                                                                                                <body name="link_32" pos="0.1 0 0">
                                                                                                                                                    <geom fromto="0 0 0 0.1 0 0" size="0.035" type="capsule" rgba="0.274 0.274 0.274 1" friction="0 0 0" />
                                                                                                                                                    <joint axis="0 0 1" class="link" name="joint_32" pos="0 0 0" range="-40.5 40.5" type="hinge" stiffness="10" />
                                                                                                                                                    <body name="link_33" pos="0.1 0 0">
                                                                                                                                                        <geom fromto="0 0 0 0.1 0 0" size="0.035" type="capsule" rgba="0.196 0.196 0.196 1" friction="0 0 0" />
                                                                                                                                                        <joint axis="0 0 1" class="link" name="joint_33" pos="0 0 0" range="-40.5 40.5" type="hinge" stiffness="10" />
                                                                                                                                                        <body name="link_34" pos="0.1 0 0">
                                                                                                                                                            <geom fromto="0 0 0 0.1 0 0" size="0.035" type="capsule" rgba="0.274 0.274 0.274 1" friction="0 0 0" />
                                                                                                                                                            <joint axis="0 0 1" class="link" name="joint_34" pos="0 0 0" range="-40.5 40.5" type="hinge" stiffness="10" />
                                                                                                                                                            <body name="link_35" pos="0.1 0 0">
                                                                                                                                                                <geom fromto="0 0 0 0.1 0 0" size="0.035" type="capsule" rgba="0.196 0.196 0.196 1" friction="0 0 0" />
                                                                                                                                                                <joint axis="0 0 1" class="link" name="joint_35" pos="0 0 0" range="-40.5 40.5" type="hinge" stiffness="10" />
                                                                                                                                                                <body name="link_36" pos="0.1 0 0">
                                                                                                                                                                    <geom fromto="0 0 0 0.1 0 0" size="0.035" type="capsule" rgba="0.274 0.274 0.274 1" friction="0 0 0" />
                                                                                                                                                                    <joint axis="0 0 1" class="link" name="joint_36" pos="0 0 0" range="-40.5 40.5" type="hinge" stiffness="10" />
                                                                                                                                                                    <body name="link_37" pos="0.1 0 0">
                                                                                                                                                                        <geom fromto="0 0 0 0.1 0 0" size="0.035" type="capsule" rgba="0.196 0.196 0.196 1" friction="0 0 0" />
                                                                                                                                                                        <joint axis="0 0 1" class="link" name="joint_37" pos="0 0 0" range="-40.5 40.5" type="hinge" stiffness="10" />
                                                                                                                                                                        <body name="link_38" pos="0.1 0 0">
                                                                                                                                                                            <geom fromto="0 0 0 0.1 0 0" size="0.035" type="capsule" rgba="0.274 0.274 0.274 1" friction="0 0 0" />
                                                                                                                                                                            <joint axis="0 0 1" class="link" name="joint_38" pos="0 0 0" range="-40.5 40.5" type="hinge" stiffness="10" />
                                                                                                                                                                            <body name="link_39" pos="0.1 0 0">
                                                                                                                                                                                <geom fromto="0 0 0 0.1 0 0" size="0.035" type="capsule" rgba="0.196 0.196 0.196 1" friction="0 0 0" />
                                                                                                                                                                                <joint axis="0 0 1" class="link" name="joint_39" pos="0 0 0" range="-40.5 40.5" type="hinge" stiffness="10" />
                                                                                                                                                                                <body name="link_40" pos="0.1 0 0">
                                                                                                                                                                                    <geom fromto="0 0 0 0.1 0 0" size="0.035" type="capsule" rgba="0.274 0.274 0.274 1" friction="0 0 0" />
                                                                                                                                                                                    <joint axis="0 0 1" class="link" name="joint_40" pos="0 0 0" range="-40.5 40.5" type="hinge" stiffness="10" />
                                                                                                                                                                                    <body name="link_41" pos="0.1 0 0">
                                                                                                                                                                                        <geom fromto="0 0 0 0.1 0 0" size="0.035" type="capsule" rgba="0.196 0.196 0.196 1" friction="0 0 0" />
                                                                                                                                                                                        <joint axis="0 0 1" class="link" name="joint_41" pos="0 0 0" range="-40.5 40.5" type="hinge" stiffness="10" />
                                                                                                                                                                                        <body name="link_42" pos="0.1 0 0">
                                                                                                                                                                                            <geom fromto="0 0 0 0.1 0 0" size="0.035" type="capsule" rgba="0.274 0.274 0.274 1" friction="0 0 0" />
                                                                                                                                                                                            <joint axis="0 0 1" class="link" name="joint_42" pos="0 0 0" range="-40.5 40.5" type="hinge" stiffness="10" />
                                                                                                                                                                                            <body name="link_43" pos="0.1 0 0">
                                                                                                                                                                                                <geom fromto="0 0 0 0.1 0 0" size="0.035" type="capsule" rgba="0.196 0.196 0.196 1" friction="0 0 0" />
                                                                                                                                                                                                <joint axis="0 0 1" class="link" name="joint_43" pos="0 0 0" range="-40.5 40.5" type="hinge" stiffness="10" />
                                                                                                                                                                                                <body name="link_44" pos="0.1 0 0">
                                                                                                                                                                                                    <geom fromto="0 0 0 0.1 0 0" size="0.035" type="capsule" rgba="0.274 0.274 0.274 1" friction="0 0 0" />
                                                                                                                                                                                                    <joint axis="0 0 1" class="link" name="joint_44" pos="0 0 0" range="-40.5 40.5" type="hinge" stiffness="10" />
                                                                                                                                                                                                    <body name="link_45" pos="0.1 0 0">
                                                                                                                                                                                                        <geom fromto="0 0 0 0.1 0 0" size="0.035" type="capsule" rgba="0.196 0.196 0.196 1" friction="0 0 0" />
                                                                                                                                                                                                        <joint axis="0 0 1" class="link" name="joint_45" pos="0 0 0" range="-40.5 40.5" type="hinge" stiffness="10" />
                                                                                                                                                                                                        <body name="link_46" pos="0.1 0 0">
                                                                                                                                                                                                            <geom fromto="0 0 0 0.1 0 0" size="0.035" type="capsule" rgba="0.274 0.274 0.274 1" friction="0 0 0" />
                                                                                                                                                                                                            <joint axis="0 0 1" class="link" name="joint_46" pos="0 0 0" range="-40.5 40.5" type="hinge" stiffness="10" />
                                                                                                                                                                                                            <body name="link_47" pos="0.1 0 0">
                                                                                                                                                                                                                <geom fromto="0 0 0 0.1 0 0" size="0.035" type="capsule" rgba="0.196 0.196 0.196 1" friction="0 0 0" />
                                                                                                                                                                                                                <joint axis="0 0 1" class="link" name="joint_47" pos="0 0 0" range="-40.5 40.5" type="hinge" stiffness="10" />
                                                                                                                                                                                                                <body name="link_48" pos="0.1 0 0">
                                                                                                                                                                                                                    <geom fromto="0 0 0 0.1 0 0" size="0.035" type="capsule" rgba="0.274 0.274 0.274 1" friction="0 0 0" />
                                                                                                                                                                                                                    <joint axis="0 0 1" class="link" name="joint_48" pos="0 0 0" range="-40.5 40.5" type="hinge" stiffness="10" />
                                                                                                                                                                                                                    <body name="link_49" pos="0.1 0 0">
                                                                                                                                                                                                                        <geom fromto="0 0 0 0.1 0 0" size="0.035" type="capsule" rgba="0.196 0.196 0.196 1" friction="0 0 0" />
                                                                                                                                                                                                                        <joint axis="0 0 1" class="link" name="joint_49" pos="0 0 0" range="-40.5 40.5" type="hinge" stiffness="10" />
                                                                                                                                                                                                                        <body name="link_50" pos="0.1 0 0">
                                                                                                                                                                                                                            <geom fromto="0 0 0 0.1 0 0" size="0.035" type="capsule" rgba="0.274 0.274 0.274 1" friction="0 0 0" />
                                                                                                                                                                                                                            <joint axis="0 0 1" class="link" name="joint_50" pos="0 0 0" range="-40.5 40.5" type="hinge" stiffness="10" />
                                                                                                                                                                                                                            <body name="link_51" pos="0.1 0 0">
                                                                                                                                                                                                                                <geom fromto="0 0 0 0.1 0 0" size="0.035" type="capsule" rgba="0.196 0.196 0.196 1" friction="0 0 0" />
                                                                                                                                                                                                                                <joint axis="0 0 1" class="link" name="joint_51" pos="0 0 0" range="-40.5 40.5" type="hinge" stiffness="10" />
                                                                                                                                                                                                                                <body name="link_52" pos="0.1 0 0">
                                                                                                                                                                                                                                    <geom fromto="0 0 0 0.1 0 0" size="0.035" type="capsule" rgba="0.274 0.274 0.274 1" friction="0 0 0" />
                                                                                                                                                                                                                                    <joint axis="0 0 1" class="link" name="joint_52" pos="0 0 0" range="-40.5 40.5" type="hinge" stiffness="10" />
                                                                                                                                                                                                                                    <body name="link_53" pos="0.1 0 0">
                                                                                                                                                                                                                                        <geom fromto="0 0 0 0.1 0 0" size="0.035" type="capsule" rgba="0.196 0.196 0.196 1" friction="0 0 0" />
                                                                                                                                                                                                                                        <joint axis="0 0 1" class="link" name="joint_53" pos="0 0 0" range="-40.5 40.5" type="hinge" stiffness="10" />
                                                                                                                                                                                                                                        <body name="link_54" pos="0.1 0 0">
                                                                                                                                                                                                                                            <geom fromto="0 0 0 0.1 0 0" size="0.035" type="capsule" rgba="0.274 0.274 0.274 1" friction="0 0 0" />
                                                                                                                                                                                                                                            <joint axis="0 0 1" class="link" name="joint_54" pos="0 0 0" range="-40.5 40.5" type="hinge" stiffness="10" />
                                                                                                                                                                                                                                            <body name="link_55" pos="0.1 0 0">
                                                                                                                                                                                                                                                <geom fromto="0 0 0 0.1 0 0" size="0.035" type="capsule" rgba="0.196 0.196 0.196 1" friction="0 0 0" />
                                                                                                                                                                                                                                                <joint axis="0 0 1" class="link" name="joint_55" pos="0 0 0" range="-40.5 40.5" type="hinge" stiffness="10" />
                                                                                                                                                                                                                                            </body>
                                                                                                                                                                                                                                        </body>
                                                                                                                                                                                                                                    </body>
                                                                                                                                                                                                                                </body>
                                                                                                                                                                                                                            </body>
                                                                                                                                                                                                                        </body>
                                                                                                                                                                                                                    </body>
                                                                                                                                                                                                                </body>
                                                                                                                                                                                                            </body>
                                                                                                                                                                                                        </body>
                                                                                                                                                                                                    </body>
                                                                                                                                                                                                </body>
                                                                                                                                                                                            </body>
                                                                                                                                                                                        </body>
                                                                                                                                                                                    </body>
                                                                                                                                                                                </body>
                                                                                                                                                                            </body>
                                                                                                                                                                        </body>
                                                                                                                                                                    </body>
                                                                                                                                                                </body>
                                                                                                                                                            </body>
                                                                                                                                                        </body>
                                                                                                                                                    </body>
                                                                                                                                                </body>
                                                                                                                                            </body>
                                                                                                                                        </body>
                                                                                                                                    </body>
                                                                                                                                </body>
                                                                                                                            </body>
                                                                                                                        </body>
                                                                                                                    </body>
                                                                                                                </body>
                                                                                                            </body>
                                                                                                        </body>
                                                                                                    </body>
                                                                                                </body>
                                                                                            </body>
                                                                                        </body>
                                                                                    </body>
                                                                                </body>
                                                                            </body>
                                                                        </body>
                                                                    </body>
                                                                </body>
                                                            </body>
                                                        </body>
                                                    </body>
                                                </body>
                                            </body>
                                        </body>
                                    </body>
                                </body>
                            </body>
                        </body>
                    </body>
                </body>
            </body>
        </body>
    </worldbody>
    <!--
		-->
    <asset>
        <mesh name="0_STLS_dir/CRL_Wing.stl" content_type="model/stl" file="STLS_dir/CRL_Wing.stl" scale="0.01 0.01 0.01" />
    </asset>
    <actuator>
        <motor class="position" ctrlrange="-40.5 40.5" joint="base_joint" name="act_base_joint" />
        <motor class="position" ctrlrange="-40.5 40.5" joint="joint_0" name="act_joint_0" />
        <motor class="position" ctrlrange="-40.5 40.5" joint="joint_1" name="act_joint_1" />
        <motor class="position" ctrlrange="-40.5 40.5" joint="joint_2" name="act_joint_2" />
        <motor class="position" ctrlrange="-40.5 40.5" joint="joint_3" name="act_joint_3" />
        <motor class="position" ctrlrange="-40.5 40.5" joint="joint_4" name="act_joint_4" />
        <motor class="position" ctrlrange="-40.5 40.5" joint="joint_5" name="act_joint_5" />
        <motor class="position" ctrlrange="-40.5 40.5" joint="joint_6" name="act_joint_6" />
        <motor class="position" ctrlrange="-40.5 40.5" joint="joint_7" name="act_joint_7" />
        <motor class="position" ctrlrange="-40.5 40.5" joint="joint_8" name="act_joint_8" />
        <motor class="position" ctrlrange="-40.5 40.5" joint="joint_9" name="act_joint_9" />
        <motor class="position" ctrlrange="-40.5 40.5" joint="joint_10" name="act_joint_10" />
        <motor class="position" ctrlrange="-40.5 40.5" joint="joint_11" name="act_joint_11" />
        <motor class="position" ctrlrange="-40.5 40.5" joint="joint_12" name="act_joint_12" />
        <motor class="position" ctrlrange="-40.5 40.5" joint="joint_13" name="act_joint_13" />
        <motor class="position" ctrlrange="-40.5 40.5" joint="joint_14" name="act_joint_14" />
        <motor class="position" ctrlrange="-40.5 40.5" joint="joint_15" name="act_joint_15" />
        <motor class="position" ctrlrange="-40.5 40.5" joint="joint_16" name="act_joint_16" />
        <motor class="position" ctrlrange="-40.5 40.5" joint="joint_17" name="act_joint_17" />
        <motor class="position" ctrlrange="-40.5 40.5" joint="joint_18" name="act_joint_18" />
        <motor class="position" ctrlrange="-40.5 40.5" joint="joint_19" name="act_joint_19" />
        <motor class="position" ctrlrange="-40.5 40.5" joint="joint_20" name="act_joint_20" />
        <motor class="position" ctrlrange="-40.5 40.5" joint="joint_21" name="act_joint_21" />
        <motor class="position" ctrlrange="-40.5 40.5" joint="joint_22" name="act_joint_22" />
        <motor class="position" ctrlrange="-40.5 40.5" joint="joint_23" name="act_joint_23" />
        <motor class="position" ctrlrange="-40.5 40.5" joint="joint_24" name="act_joint_24" />
        <motor class="position" ctrlrange="-40.5 40.5" joint="joint_25" name="act_joint_25" />
        <motor class="position" ctrlrange="-40.5 40.5" joint="joint_26" name="act_joint_26" />
        <motor class="position" ctrlrange="-40.5 40.5" joint="joint_27" name="act_joint_27" />
        <motor class="position" ctrlrange="-40.5 40.5" joint="joint_28" name="act_joint_28" />
        <motor class="position" ctrlrange="-40.5 40.5" joint="joint_29" name="act_joint_29" />
        <motor class="position" ctrlrange="-40.5 40.5" joint="joint_30" name="act_joint_30" />
        <motor class="position" ctrlrange="-40.5 40.5" joint="joint_31" name="act_joint_31" />
        <motor class="position" ctrlrange="-40.5 40.5" joint="joint_32" name="act_joint_32" />
        <motor class="position" ctrlrange="-40.5 40.5" joint="joint_33" name="act_joint_33" />
        <motor class="position" ctrlrange="-40.5 40.5" joint="joint_34" name="act_joint_34" />
        <motor class="position" ctrlrange="-40.5 40.5" joint="joint_35" name="act_joint_35" />
        <motor class="position" ctrlrange="-40.5 40.5" joint="joint_36" name="act_joint_36" />
        <motor class="position" ctrlrange="-40.5 40.5" joint="joint_37" name="act_joint_37" />
        <motor class="position" ctrlrange="-40.5 40.5" joint="joint_38" name="act_joint_38" />
        <motor class="position" ctrlrange="-40.5 40.5" joint="joint_39" name="act_joint_39" />
        <motor class="position" ctrlrange="-40.5 40.5" joint="joint_40" name="act_joint_40" />
        <motor class="position" ctrlrange="-40.5 40.5" joint="joint_41" name="act_joint_41" />
        <motor class="position" ctrlrange="-40.5 40.5" joint="joint_42" name="act_joint_42" />
        <motor class="position" ctrlrange="-40.5 40.5" joint="joint_43" name="act_joint_43" />
        <motor class="position" ctrlrange="-40.5 40.5" joint="joint_44" name="act_joint_44" />
        <motor class="position" ctrlrange="-40.5 40.5" joint="joint_45" name="act_joint_45" />
        <motor class="position" ctrlrange="-40.5 40.5" joint="joint_46" name="act_joint_46" />
        <motor class="position" ctrlrange="-40.5 40.5" joint="joint_47" name="act_joint_47" />
        <motor class="position" ctrlrange="-40.5 40.5" joint="joint_48" name="act_joint_48" />
        <motor class="position" ctrlrange="-40.5 40.5" joint="joint_49" name="act_joint_49" />
        <motor class="position" ctrlrange="-40.5 40.5" joint="joint_50" name="act_joint_50" />
        <motor class="position" ctrlrange="-40.5 40.5" joint="joint_51" name="act_joint_51" />
        <motor class="position" ctrlrange="-40.5 40.5" joint="joint_52" name="act_joint_52" />
        <motor class="position" ctrlrange="-40.5 40.5" joint="joint_53" name="act_joint_53" />
        <motor class="position" ctrlrange="-40.5 40.5" joint="joint_54" name="act_joint_54" />
        <motor class="position" ctrlrange="-40.5 40.5" joint="joint_55" name="act_joint_55" />
    </actuator>
    <asset />
    <option gravity="0 0 -1.8" />
</mujoco>