<mujoco>
    <!-- === Configuration parameter stuff, default values === -->
    <default>
        <default class="position">
            <position ctrllimited="true" forcelimited="false" />
        </default>
        <default class="geom0">
            <geom conaffinity="0" contype="1" friction="1 0.005 0.001" margin="0.001" rgba="0.75 0.6 0.5 1" solimp="0.95 0.95 0.01" solref="0.008 1" />
        </default>
        <default class="link">
            <joint armature="0.1" damping="5" limited="true" stiffness="0" />
        </default>
    </default>
    <!-- === Physical robot definitions === -->
    <worldbody>
        <light diffuse="1.0 1.0 1.0" pos="0 0 10" dir="0 0 -1" />
        <geom type="plane" size="100 100 0.1" rgba="0.46 0.86 1 1" />
        <!--
		-->
    <body name="obstacle_custom_22" pos="1.2825 0.9375 0">
            <geom name="obstacle_custom_22_geom" size="0.08249999999999999" rgba="0.98 0.75 1 1" fromto="0 0 0 0 0 0.2" type="capsule" />
        </body>
        <body name="obstacle_custom_21" pos="1.11 0.6225 0">
            <geom name="obstacle_custom_21_geom" size="0.08249999999999999" rgba="0.98 0.75 1 1" fromto="0 0 0 0 0 0.2" type="capsule" />
        </body>
        <body name="obstacle_custom_20" pos="1.005 0.4725 0">
            <geom name="obstacle_custom_20_geom" size="0.08249999999999999" rgba="0.98 0.75 1 1" fromto="0 0 0 0 0 0.2" type="capsule" />
        </body>
        <body name="obstacle_custom_19" pos="0.7575 0.4275 0">
            <geom name="obstacle_custom_19_geom" size="0.08249999999999999" rgba="0.98 0.75 1 1" fromto="0 0 0 0 0 0.2" type="capsule" />
        </body>
        <body name="obstacle_custom_18" pos="0.5475 0.39 0">
            <geom name="obstacle_custom_18_geom" size="0.08249999999999999" rgba="0.98 0.75 1 1" fromto="0 0 0 0 0 0.2" type="capsule" />
        </body>
        <body name="obstacle_custom_17" pos="0.3375 0.345 0">
            <geom name="obstacle_custom_17_geom" size="0.08249999999999999" rgba="0.98 0.75 1 1" fromto="0 0 0 0 0 0.2" type="capsule" />
        </body>
        <body name="obstacle_custom_16" pos="0.1725 0.5175 0">
            <geom name="obstacle_custom_16_geom" size="0.08249999999999999" rgba="0.98 0.75 1 1" fromto="0 0 0 0 0 0.2" type="capsule" />
        </body>
        <body name="obstacle_custom_15" pos="-0.12 0.7275 0">
            <geom name="obstacle_custom_15_geom" size="0.08249999999999999" rgba="0.98 0.75 1 1" fromto="0 0 0 0 0 0.2" type="capsule" />
        </body>
        <body name="obstacle_custom_14" pos="0.255 1.65 2">
            <joint name="obstacle_custom_14_joint" type="free" damping="0.001" />
            <geom name="obstacle_custom_14_geom" size="0.2625" rgba="0 0 0 1" fromto="0 0 0 0 0 0.01" type="capsule" />
        </body>
        <body name="obstacle_custom_13" pos="-0.435 1.6725 2">
            <joint name="obstacle_custom_13_joint" type="free" damping="0.001" />
            <geom name="obstacle_custom_13_geom" size="0.2625" rgba="0 0 0 1" fromto="0 0 0 0 0 0.01" type="capsule" />
        </body>
        <body name="obstacle_custom_12" pos="0.945 -0.8475 2">
            <joint name="obstacle_custom_12_joint" type="free" damping="0.001" />
            <geom name="obstacle_custom_12_geom" size="0.0375" rgba="0 0 0 1" fromto="0 0 0 0 0 0.01" type="capsule" />
        </body>
        <body name="obstacle_custom_11" pos="1.0725 -0.735 2">
            <joint name="obstacle_custom_11_joint" type="free" damping="0.001" />
            <geom name="obstacle_custom_11_geom" size="0.0375" rgba="0 0 0 1" fromto="0 0 0 0 0 0.01" type="capsule" />
        </body>
        <body name="obstacle_custom_10" pos="1.2 -0.48 2">
            <joint name="obstacle_custom_10_joint" type="free" damping="0.001" />
            <geom name="obstacle_custom_10_geom" size="0.0375" rgba="0 0 0 1" fromto="0 0 0 0 0 0.01" type="capsule" />
        </body>
        <body name="obstacle_custom_9" pos="0.8775 -0.48 2">
            <joint name="obstacle_custom_9_joint" type="free" damping="0.001" />
            <geom name="obstacle_custom_9_geom" size="0.0375" rgba="0 0 0 1" fromto="0 0 0 0 0 0.01" type="capsule" />
        </body>
        <body name="obstacle_custom_8" pos="0.855 -0.645 2">
            <joint name="obstacle_custom_8_joint" type="free" damping="0.001" />
            <geom name="obstacle_custom_8_geom" size="0.0375" rgba="0 0 0 1" fromto="0 0 0 0 0 0.01" type="capsule" />
        </body>
        <body name="obstacle_custom_7" pos="0.6975 -0.7725 2">
            <joint name="obstacle_custom_7_joint" type="free" damping="0.001" />
            <geom name="obstacle_custom_7_geom" size="0.0375" rgba="0 0 0 1" fromto="0 0 0 0 0 0.01" type="capsule" />
        </body>
        <body name="obstacle_custom_6" pos="0.5025 -0.675 2">
            <joint name="obstacle_custom_6_joint" type="free" damping="0.001" />
            <geom name="obstacle_custom_6_geom" size="0.0375" rgba="0 0 0 1" fromto="0 0 0 0 0 0.01" type="capsule" />
        </body>
        <body name="obstacle_custom_5" pos="0.7275 -0.48 2">
            <joint name="obstacle_custom_5_joint" type="free" damping="0.001" />
            <geom name="obstacle_custom_5_geom" size="0.0375" rgba="0 0 0 1" fromto="0 0 0 0 0 0.01" type="capsule" />
        </body>
        <body name="obstacle_custom_4" pos="0.87 -0.2625 2">
            <joint name="obstacle_custom_4_joint" type="free" damping="0.001" />
            <geom name="obstacle_custom_4_geom" size="0.0375" rgba="0 0 0 1" fromto="0 0 0 0 0 0.01" type="capsule" />
        </body>
        <body name="obstacle_custom_3" pos="0.7425 -0.09 2">
            <joint name="obstacle_custom_3_joint" type="free" damping="0.001" />
            <geom name="obstacle_custom_3_geom" size="0.0375" rgba="0 0 0 1" fromto="0 0 0 0 0 0.01" type="capsule" />
        </body>
        <body name="obstacle_custom_2" pos="0.6225 -0.105 2">
            <joint name="obstacle_custom_2_joint" type="free" damping="0.001" />
            <geom name="obstacle_custom_2_geom" size="0.0375" rgba="0 0 0 1" fromto="0 0 0 0 0 0.01" type="capsule" />
        </body>
        <body name="obstacle_custom_1" pos="0.6675 -0.2325 2">
            <joint name="obstacle_custom_1_joint" type="free" damping="0.001" />
            <geom name="obstacle_custom_1_geom" size="0.0375" rgba="0 0 0 1" fromto="0 0 0 0 0 0.01" type="capsule" />
        </body>
        <body name="obstacle_custom_0" pos="0.3075 -0.3375 0">
            <geom name="obstacle_custom_0_geom" size="0.18" rgba="0.98 0.75 1 1" fromto="0 0 0 0 0 0.2" type="capsule" />
        </body>
        <body name="base" pos="0 0 0.04">
            <geom size="0.05" type="sphere" />
            <body name="base_link" pos="0.05 0 0">
                <geom class="geom0" fromto="0 0 0 0.07 0 0" size="0.035" type="capsule" />
                <joint axis="0 0 1" class="link" name="base_joint" pos="0 0 0" range="-40.5 40.5" type="hinge" />
                <body name="link_0" pos="0.07 0 0">
                    <geom class="geom0" fromto="0 0 0 0.07 0 0" size="0.035" type="capsule" />
                    <joint axis="0 0 1" class="link" name="joint_0" pos="0 0 0" range="-40.5 40.5" type="hinge" stiffness="10" />
                    <body name="link_1" pos="0.07 0 0">
                        <geom class="geom0" fromto="0 0 0 0.07 0 0" size="0.035" type="capsule" />
                        <joint axis="0 0 1" class="link" name="joint_1" pos="0 0 0" range="-40.5 40.5" type="hinge" stiffness="10" />
                        <body name="link_2" pos="0.07 0 0">
                            <geom class="geom0" fromto="0 0 0 0.07 0 0" size="0.035" type="capsule" />
                            <joint axis="0 0 1" class="link" name="joint_2" pos="0 0 0" range="-40.5 40.5" type="hinge" stiffness="10" />
                            <body name="link_3" pos="0.07 0 0">
                                <geom class="geom0" fromto="0 0 0 0.07 0 0" size="0.035" type="capsule" />
                                <joint axis="0 0 1" class="link" name="joint_3" pos="0 0 0" range="-40.5 40.5" type="hinge" stiffness="10" />
                                <body name="link_4" pos="0.07 0 0">
                                    <geom class="geom0" fromto="0 0 0 0.07 0 0" size="0.035" type="capsule" />
                                    <joint axis="0 0 1" class="link" name="joint_4" pos="0 0 0" range="-40.5 40.5" type="hinge" stiffness="10" />
                                    <body name="link_5" pos="0.07 0 0">
                                        <geom class="geom0" fromto="0 0 0 0.07 0 0" size="0.035" type="capsule" />
                                        <joint axis="0 0 1" class="link" name="joint_5" pos="0 0 0" range="-40.5 40.5" type="hinge" stiffness="10" />
                                        <body name="link_6" pos="0.07 0 0">
                                            <geom class="geom0" fromto="0 0 0 0.07 0 0" size="0.035" type="capsule" />
                                            <joint axis="0 0 1" class="link" name="joint_6" pos="0 0 0" range="-40.5 40.5" type="hinge" stiffness="10" />
                                            <body name="link_7" pos="0.07 0 0">
                                                <geom class="geom0" fromto="0 0 0 0.07 0 0" size="0.035" type="capsule" />
                                                <joint axis="0 0 1" class="link" name="joint_7" pos="0 0 0" range="-40.5 40.5" type="hinge" stiffness="10" />
                                                <body name="link_8" pos="0.07 0 0">
                                                    <geom class="geom0" fromto="0 0 0 0.07 0 0" size="0.035" type="capsule" />
                                                    <joint axis="0 0 1" class="link" name="joint_8" pos="0 0 0" range="-40.5 40.5" type="hinge" stiffness="10" />
                                                    <body name="link_9" pos="0.07 0 0">
                                                        <geom class="geom0" fromto="0 0 0 0.07 0 0" size="0.035" type="capsule" />
                                                        <joint axis="0 0 1" class="link" name="joint_9" pos="0 0 0" range="-40.5 40.5" type="hinge" stiffness="10" />
                                                        <body name="link_10" pos="0.07 0 0">
                                                            <geom class="geom0" fromto="0 0 0 0.07 0 0" size="0.035" type="capsule" />
                                                            <joint axis="0 0 1" class="link" name="joint_10" pos="0 0 0" range="-40.5 40.5" type="hinge" stiffness="10" />
                                                            <body name="link_11" pos="0.07 0 0">
                                                                <geom class="geom0" fromto="0 0 0 0.07 0 0" size="0.035" type="capsule" />
                                                                <joint axis="0 0 1" class="link" name="joint_11" pos="0 0 0" range="-40.5 40.5" type="hinge" stiffness="10" />
                                                                <body name="link_12" pos="0.07 0 0">
                                                                    <geom class="geom0" fromto="0 0 0 0.07 0 0" size="0.035" type="capsule" />
                                                                    <joint axis="0 0 1" class="link" name="joint_12" pos="0 0 0" range="-40.5 40.5" type="hinge" stiffness="10" />
                                                                    <body name="link_13" pos="0.07 0 0">
                                                                        <geom class="geom0" fromto="0 0 0 0.07 0 0" size="0.035" type="capsule" />
                                                                        <joint axis="0 0 1" class="link" name="joint_13" pos="0 0 0" range="-40.5 40.5" type="hinge" stiffness="10" />
                                                                        <body name="link_14" pos="0.07 0 0">
                                                                            <geom class="geom0" fromto="0 0 0 0.07 0 0" size="0.035" type="capsule" />
                                                                            <joint axis="0 0 1" class="link" name="joint_14" pos="0 0 0" range="-40.5 40.5" type="hinge" stiffness="10" />
                                                                            <body name="link_15" pos="0.07 0 0">
                                                                                <geom class="geom0" fromto="0 0 0 0.07 0 0" size="0.035" type="capsule" />
                                                                                <joint axis="0 0 1" class="link" name="joint_15" pos="0 0 0" range="-40.5 40.5" type="hinge" stiffness="10" />
                                                                                <body name="link_16" pos="0.07 0 0">
                                                                                    <geom class="geom0" fromto="0 0 0 0.07 0 0" size="0.035" type="capsule" />
                                                                                    <joint axis="0 0 1" class="link" name="joint_16" pos="0 0 0" range="-40.5 40.5" type="hinge" stiffness="10" />
                                                                                    <body name="link_17" pos="0.07 0 0">
                                                                                        <geom class="geom0" fromto="0 0 0 0.07 0 0" size="0.035" type="capsule" />
                                                                                        <joint axis="0 0 1" class="link" name="joint_17" pos="0 0 0" range="-40.5 40.5" type="hinge" stiffness="10" />
                                                                                        <body name="link_18" pos="0.07 0 0">
                                                                                            <geom class="geom0" fromto="0 0 0 0.07 0 0" size="0.035" type="capsule" />
                                                                                            <joint axis="0 0 1" class="link" name="joint_18" pos="0 0 0" range="-40.5 40.5" type="hinge" stiffness="10" />
                                                                                            <body name="link_19" pos="0.07 0 0">
                                                                                                <geom class="geom0" fromto="0 0 0 0.07 0 0" size="0.035" type="capsule" />
                                                                                                <joint axis="0 0 1" class="link" name="joint_19" pos="0 0 0" range="-40.5 40.5" type="hinge" stiffness="10" />
                                                                                                <body name="link_20" pos="0.07 0 0">
                                                                                                    <geom class="geom0" fromto="0 0 0 0.07 0 0" size="0.035" type="capsule" />
                                                                                                    <joint axis="0 0 1" class="link" name="joint_20" pos="0 0 0" range="-40.5 40.5" type="hinge" stiffness="10" />
                                                                                                    <body name="link_21" pos="0.07 0 0">
                                                                                                        <geom class="geom0" fromto="0 0 0 0.07 0 0" size="0.035" type="capsule" />
                                                                                                        <joint axis="0 0 1" class="link" name="joint_21" pos="0 0 0" range="-40.5 40.5" type="hinge" stiffness="10" />
                                                                                                        <body name="link_22" pos="0.07 0 0">
                                                                                                            <geom class="geom0" fromto="0 0 0 0.07 0 0" size="0.035" type="capsule" />
                                                                                                            <joint axis="0 0 1" class="link" name="joint_22" pos="0 0 0" range="-40.5 40.5" type="hinge" stiffness="10" />
                                                                                                            <body name="link_23" pos="0.07 0 0">
                                                                                                                <geom class="geom0" fromto="0 0 0 0.07 0 0" size="0.035" type="capsule" />
                                                                                                                <joint axis="0 0 1" class="link" name="joint_23" pos="0 0 0" range="-40.5 40.5" type="hinge" stiffness="10" />
                                                                                                                <body name="link_24" pos="0.07 0 0">
                                                                                                                    <geom class="geom0" fromto="0 0 0 0.07 0 0" size="0.035" type="capsule" />
                                                                                                                    <joint axis="0 0 1" class="link" name="joint_24" pos="0 0 0" range="-40.5 40.5" type="hinge" stiffness="10" />
                                                                                                                    <body name="link_25" pos="0.07 0 0">
                                                                                                                        <geom class="geom0" fromto="0 0 0 0.07 0 0" size="0.035" type="capsule" />
                                                                                                                        <joint axis="0 0 1" class="link" name="joint_25" pos="0 0 0" range="-40.5 40.5" type="hinge" stiffness="10" />
                                                                                                                        <body name="link_26" pos="0.07 0 0">
                                                                                                                            <geom class="geom0" fromto="0 0 0 0.07 0 0" size="0.035" type="capsule" />
                                                                                                                            <joint axis="0 0 1" class="link" name="joint_26" pos="0 0 0" range="-40.5 40.5" type="hinge" stiffness="10" />
                                                                                                                            <body name="link_27" pos="0.07 0 0">
                                                                                                                                <geom class="geom0" fromto="0 0 0 0.07 0 0" size="0.035" type="capsule" />
                                                                                                                                <joint axis="0 0 1" class="link" name="joint_27" pos="0 0 0" range="-40.5 40.5" type="hinge" stiffness="10" />
                                                                                                                                <body name="link_28" pos="0.07 0 0">
                                                                                                                                    <geom class="geom0" fromto="0 0 0 0.07 0 0" size="0.035" type="capsule" />
                                                                                                                                    <joint axis="0 0 1" class="link" name="joint_28" pos="0 0 0" range="-40.5 40.5" type="hinge" stiffness="10" />
                                                                                                                                    <body name="link_29" pos="0.07 0 0">
                                                                                                                                        <geom class="geom0" fromto="0 0 0 0.07 0 0" size="0.035" type="capsule" />
                                                                                                                                        <joint axis="0 0 1" class="link" name="joint_29" pos="0 0 0" range="-40.5 40.5" type="hinge" stiffness="10" />
                                                                                                                                    </body>
                                                                                                                                </body>
                                                                                                                            </body>
                                                                                                                        </body>
                                                                                                                    </body>
                                                                                                                </body>
                                                                                                            </body>
                                                                                                        </body>
                                                                                                    </body>
                                                                                                </body>
                                                                                            </body>
                                                                                        </body>
                                                                                    </body>
                                                                                </body>
                                                                            </body>
                                                                        </body>
                                                                    </body>
                                                                </body>
                                                            </body>
                                                        </body>
                                                    </body>
                                                </body>
                                            </body>
                                        </body>
                                    </body>
                                </body>
                            </body>
                        </body>
                    </body>
                </body>
            </body>
        </body>
    </worldbody>
    <!--
		-->
    <actuator>
        <motor class="position" ctrlrange="-40.5 40.5" joint="base_joint" name="act_base_joint" />
        <motor class="position" ctrlrange="-40.5 40.5" joint="joint_0" name="act_joint_0" />
        <motor class="position" ctrlrange="-40.5 40.5" joint="joint_1" name="act_joint_1" />
        <motor class="position" ctrlrange="-40.5 40.5" joint="joint_2" name="act_joint_2" />
        <motor class="position" ctrlrange="-40.5 40.5" joint="joint_3" name="act_joint_3" />
        <motor class="position" ctrlrange="-40.5 40.5" joint="joint_4" name="act_joint_4" />
        <motor class="position" ctrlrange="-40.5 40.5" joint="joint_5" name="act_joint_5" />
        <motor class="position" ctrlrange="-40.5 40.5" joint="joint_6" name="act_joint_6" />
        <motor class="position" ctrlrange="-40.5 40.5" joint="joint_7" name="act_joint_7" />
        <motor class="position" ctrlrange="-40.5 40.5" joint="joint_8" name="act_joint_8" />
        <motor class="position" ctrlrange="-40.5 40.5" joint="joint_9" name="act_joint_9" />
        <motor class="position" ctrlrange="-40.5 40.5" joint="joint_10" name="act_joint_10" />
        <motor class="position" ctrlrange="-40.5 40.5" joint="joint_11" name="act_joint_11" />
        <motor class="position" ctrlrange="-40.5 40.5" joint="joint_12" name="act_joint_12" />
        <motor class="position" ctrlrange="-40.5 40.5" joint="joint_13" name="act_joint_13" />
        <motor class="position" ctrlrange="-40.5 40.5" joint="joint_14" name="act_joint_14" />
        <motor class="position" ctrlrange="-40.5 40.5" joint="joint_15" name="act_joint_15" />
        <motor class="position" ctrlrange="-40.5 40.5" joint="joint_16" name="act_joint_16" />
        <motor class="position" ctrlrange="-40.5 40.5" joint="joint_17" name="act_joint_17" />
        <motor class="position" ctrlrange="-40.5 40.5" joint="joint_18" name="act_joint_18" />
        <motor class="position" ctrlrange="-40.5 40.5" joint="joint_19" name="act_joint_19" />
        <motor class="position" ctrlrange="-40.5 40.5" joint="joint_20" name="act_joint_20" />
        <motor class="position" ctrlrange="-40.5 40.5" joint="joint_21" name="act_joint_21" />
        <motor class="position" ctrlrange="-40.5 40.5" joint="joint_22" name="act_joint_22" />
        <motor class="position" ctrlrange="-40.5 40.5" joint="joint_23" name="act_joint_23" />
        <motor class="position" ctrlrange="-40.5 40.5" joint="joint_24" name="act_joint_24" />
        <motor class="position" ctrlrange="-40.5 40.5" joint="joint_25" name="act_joint_25" />
        <motor class="position" ctrlrange="-40.5 40.5" joint="joint_26" name="act_joint_26" />
        <motor class="position" ctrlrange="-40.5 40.5" joint="joint_27" name="act_joint_27" />
        <motor class="position" ctrlrange="-40.5 40.5" joint="joint_28" name="act_joint_28" />
        <motor class="position" ctrlrange="-40.5 40.5" joint="joint_29" name="act_joint_29" />
    </actuator>
    <option gravity="0 0 -1.8" />
</mujoco>