<mujoco>
    <!-- === Configuration parameter stuff, default values === -->
    <default>
        <default class="position">
            <position ctrllimited="true" forcelimited="false" />
        </default>
        <default class="geom0">
            <geom conaffinity="0" contype="1" friction="0 0.0 0.0" margin="0.001" rgba="0.75 0.6 0.5 1" solimp="0.95 0.95 0.01" solref="0.008 1" />
        </default>
        <default class="link">
            <joint armature="0.1" damping="5" limited="true" stiffness="0" />
        </default>
    </default>
    <!-- === Physical robot definitions === -->
    <worldbody>
        <light pos="0 0 10" dir="0 0 -1" castshadow="false" />
        <geom type="plane" size="100 100 0.1" material="grid" />
        <!--
		-->
    <body name="obstacle_custom_30" pos="2.3325 -0.87 2">
            <joint name="obstacle_custom_30_joint" type="free" damping="0.001" />
            <geom name="obstacle_custom_30_geom" size="0.0375" rgba="0 0 0 1" fromto="0 0 0 0 0 0.01" type="capsule" />
        </body>
        <body name="obstacle_custom_29" pos="2.2125 -1.11 2">
            <joint name="obstacle_custom_29_joint" type="free" damping="0.001" />
            <geom name="obstacle_custom_29_geom" size="0.0375" rgba="0 0 0 1" fromto="0 0 0 0 0 0.01" type="capsule" />
        </body>
        <body name="obstacle_custom_28" pos="2.0175 -0.8775 2">
            <joint name="obstacle_custom_28_joint" type="free" damping="0.001" />
            <geom name="obstacle_custom_28_geom" size="0.0375" rgba="0 0 0 1" fromto="0 0 0 0 0 0.01" type="capsule" />
        </body>
        <body name="obstacle_custom_27" pos="2.0775 -1.035 2">
            <joint name="obstacle_custom_27_joint" type="free" damping="0.001" />
            <geom name="obstacle_custom_27_geom" size="0.0375" rgba="0 0 0 1" fromto="0 0 0 0 0 0.01" type="capsule" />
        </body>
        <body name="obstacle_custom_26" pos="2.265 -1.245 2">
            <joint name="obstacle_custom_26_joint" type="free" damping="0.001" />
            <geom name="obstacle_custom_26_geom" size="0.0375" rgba="0 0 0 1" fromto="0 0 0 0 0 0.01" type="capsule" />
        </body>
        <body name="obstacle_custom_25" pos="2.325 -1.095 2">
            <joint name="obstacle_custom_25_joint" type="free" damping="0.001" />
            <geom name="obstacle_custom_25_geom" size="0.0375" rgba="0 0 0 1" fromto="0 0 0 0 0 0.01" type="capsule" />
        </body>
        <body name="obstacle_custom_24" pos="2.175 -0.915 2">
            <joint name="obstacle_custom_24_joint" type="free" damping="0.001" />
            <geom name="obstacle_custom_24_geom" size="0.0375" rgba="0 0 0 1" fromto="0 0 0 0 0 0.01" type="capsule" />
        </body>
        <body name="obstacle_custom_23" pos="2.1525 -0.765 2">
            <joint name="obstacle_custom_23_joint" type="free" damping="0.001" />
            <geom name="obstacle_custom_23_geom" size="0.0375" rgba="0 0 0 1" fromto="0 0 0 0 0 0.01" type="capsule" />
        </body>
        <body name="obstacle_custom_22" pos="2.1075 -0.72 2">
            <joint name="obstacle_custom_22_joint" type="free" damping="0.001" />
            <geom name="obstacle_custom_22_geom" size="0.0375" rgba="0 0 0 1" fromto="0 0 0 0 0 0.01" type="capsule" />
        </body>
        <body name="obstacle_custom_21" pos="1.995 -0.8025 2">
            <joint name="obstacle_custom_21_joint" type="free" damping="0.001" />
            <geom name="obstacle_custom_21_geom" size="0.0375" rgba="0 0 0 1" fromto="0 0 0 0 0 0.01" type="capsule" />
        </body>
        <body name="obstacle_custom_20" pos="1.8975 -0.84 2">
            <joint name="obstacle_custom_20_joint" type="free" damping="0.001" />
            <geom name="obstacle_custom_20_geom" size="0.0375" rgba="0 0 0 1" fromto="0 0 0 0 0 0.01" type="capsule" />
        </body>
        <body name="obstacle_custom_19" pos="1.8525 -0.9 2">
            <joint name="obstacle_custom_19_joint" type="free" damping="0.001" />
            <geom name="obstacle_custom_19_geom" size="0.0375" rgba="0 0 0 1" fromto="0 0 0 0 0 0.01" type="capsule" />
        </body>
        <body name="obstacle_custom_18" pos="1.32 0.285 0">
            <geom name="obstacle_custom_18_geom" size="0.075" rgba="0.98 0.75 1 1" fromto="0 0 0 0 0 0.2" type="capsule" />
        </body>
        <body name="obstacle_custom_17" pos="1.5525 0.285 0">
            <geom name="obstacle_custom_17_geom" size="0.075" rgba="0.98 0.75 1 1" fromto="0 0 0 0 0 0.2" type="capsule" />
        </body>
        <body name="obstacle_custom_16" pos="1.695 0.285 0">
            <geom name="obstacle_custom_16_geom" size="0.075" rgba="0.98 0.75 1 1" fromto="0 0 0 0 0 0.2" type="capsule" />
        </body>
        <body name="obstacle_custom_15" pos="1.815 0.2775 0">
            <geom name="obstacle_custom_15_geom" size="0.075" rgba="0.98 0.75 1 1" fromto="0 0 0 0 0 0.2" type="capsule" />
        </body>
        <body name="obstacle_custom_14" pos="1.935 0.2775 0">
            <geom name="obstacle_custom_14_geom" size="0.075" rgba="0.98 0.75 1 1" fromto="0 0 0 0 0 0.2" type="capsule" />
        </body>
        <body name="obstacle_custom_13" pos="2.025 0.165 0">
            <geom name="obstacle_custom_13_geom" size="0.075" rgba="0.98 0.75 1 1" fromto="0 0 0 0 0 0.2" type="capsule" />
        </body>
        <body name="obstacle_custom_12" pos="2.0625 0.015 0">
            <geom name="obstacle_custom_12_geom" size="0.075" rgba="0.98 0.75 1 1" fromto="0 0 0 0 0 0.2" type="capsule" />
        </body>
        <body name="obstacle_custom_11" pos="2.07 -0.105 0">
            <geom name="obstacle_custom_11_geom" size="0.075" rgba="0.98 0.75 1 1" fromto="0 0 0 0 0 0.2" type="capsule" />
        </body>
        <body name="obstacle_custom_10" pos="2.055 -0.2325 0">
            <geom name="obstacle_custom_10_geom" size="0.075" rgba="0.98 0.75 1 1" fromto="0 0 0 0 0 0.2" type="capsule" />
        </body>
        <body name="obstacle_custom_9" pos="2.0325 -0.3225 0">
            <geom name="obstacle_custom_9_geom" size="0.075" rgba="0.98 0.75 1 1" fromto="0 0 0 0 0 0.2" type="capsule" />
        </body>
        <body name="obstacle_custom_8" pos="2.01 -0.4575 0">
            <geom name="obstacle_custom_8_geom" size="0.075" rgba="0.98 0.75 1 1" fromto="0 0 0 0 0 0.2" type="capsule" />
        </body>
        <body name="obstacle_custom_7" pos="1.98 -0.5325 0">
            <geom name="obstacle_custom_7_geom" size="0.075" rgba="0.98 0.75 1 1" fromto="0 0 0 0 0 0.2" type="capsule" />
        </body>
        <body name="obstacle_custom_6" pos="1.9425 -0.6075 0">
            <geom name="obstacle_custom_6_geom" size="0.075" rgba="0.98 0.75 1 1" fromto="0 0 0 0 0 0.2" type="capsule" />
        </body>
        <body name="obstacle_custom_5" pos="1.905 -0.6825 0">
            <geom name="obstacle_custom_5_geom" size="0.075" rgba="0.98 0.75 1 1" fromto="0 0 0 0 0 0.2" type="capsule" />
        </body>
        <body name="obstacle_custom_4" pos="1.845 -0.735 0">
            <geom name="obstacle_custom_4_geom" size="0.075" rgba="0.98 0.75 1 1" fromto="0 0 0 0 0 0.2" type="capsule" />
        </body>
        <body name="obstacle_custom_3" pos="1.7475 -0.8025 0">
            <geom name="obstacle_custom_3_geom" size="0.075" rgba="0.98 0.75 1 1" fromto="0 0 0 0 0 0.2" type="capsule" />
        </body>
        <body name="obstacle_custom_2" pos="1.32 -0.3825 0">
            <geom name="obstacle_custom_2_geom" size="0.075" rgba="0.98 0.75 1 1" fromto="0 0 0 0 0 0.2" type="capsule" />
        </body>
        <body name="obstacle_custom_1" pos="1.6875 0.2925 0">
            <geom name="obstacle_custom_1_geom" size="0.075" rgba="0.98 0.75 1 1" fromto="0 0 0 0 0 0.2" type="capsule" />
        </body>
        <body name="obstacle_custom_0" pos="1.41 0.2925 0">
            <geom name="obstacle_custom_0_geom" size="0.075" rgba="0.98 0.75 1 1" fromto="0 0 0 0 0 0.2" type="capsule" />
        </body>
        <body name="base" pos="0 0 0.05">
            <geom size="0.05" type="sphere" />
            <joint axis="1 0 0" name="sphere_position" pos="0 0 0" range="-2 2" type="slide" />
            <body name="base_link" pos="0.05 0 0">
                <geom class="geom0" fromto="0 0 0 0.05 0 0" size="0.035" type="capsule" />
                <joint axis="0 0 1" class="link" name="base_joint" pos="0 0 0" range="-40.5 40.5" type="hinge" />
                <body name="link_0" pos="0.05 0 0">
                    <geom fromto="0 0 0 0.05 0 0" size="0.035" type="capsule" rgba="0.4 0.1 1 1" />
                    <joint axis="0 0 1" class="link" name="joint_0" pos="0 0 0" range="-40.5 40.5" type="hinge" stiffness="10" />
                    <body name="link_1" pos="0.05 0 0">
                        <geom fromto="0 0 0 0.05 0 0" size="0.035" type="capsule" rgba="0.1 0 1 1" />
                        <joint axis="0 0 1" class="link" name="joint_1" pos="0 0 0" range="-40.5 40.5" type="hinge" stiffness="10" />
                        <body name="link_2" pos="0.05 0 0">
                            <geom fromto="0 0 0 0.05 0 0" size="0.035" type="capsule" rgba="0.4 0.1 1 1" />
                            <joint axis="0 0 1" class="link" name="joint_2" pos="0 0 0" range="-40.5 40.5" type="hinge" stiffness="10" />
                            <body name="link_3" pos="0.05 0 0">
                                <geom fromto="0 0 0 0.05 0 0" size="0.035" type="capsule" rgba="0.1 0 1 1" />
                                <joint axis="0 0 1" class="link" name="joint_3" pos="0 0 0" range="-40.5 40.5" type="hinge" stiffness="10" />
                                <body name="link_4" pos="0.05 0 0">
                                    <geom fromto="0 0 0 0.05 0 0" size="0.035" type="capsule" rgba="0.4 0.1 1 1" />
                                    <joint axis="0 0 1" class="link" name="joint_4" pos="0 0 0" range="-40.5 40.5" type="hinge" stiffness="10" />
                                    <body name="link_5" pos="0.05 0 0">
                                        <geom fromto="0 0 0 0.05 0 0" size="0.035" type="capsule" rgba="0.1 0 1 1" />
                                        <joint axis="0 0 1" class="link" name="joint_5" pos="0 0 0" range="-40.5 40.5" type="hinge" stiffness="10" />
                                        <body name="link_6" pos="0.05 0 0">
                                            <geom fromto="0 0 0 0.05 0 0" size="0.035" type="capsule" rgba="0.4 0.1 1 1" />
                                            <joint axis="0 0 1" class="link" name="joint_6" pos="0 0 0" range="-40.5 40.5" type="hinge" stiffness="10" />
                                            <body name="link_7" pos="0.05 0 0">
                                                <geom fromto="0 0 0 0.05 0 0" size="0.035" type="capsule" rgba="0.1 0 1 1" />
                                                <joint axis="0 0 1" class="link" name="joint_7" pos="0 0 0" range="-40.5 40.5" type="hinge" stiffness="10" />
                                                <body name="link_8" pos="0.05 0 0">
                                                    <geom fromto="0 0 0 0.05 0 0" size="0.035" type="capsule" rgba="0.4 0.1 1 1" />
                                                    <joint axis="0 0 1" class="link" name="joint_8" pos="0 0 0" range="-40.5 40.5" type="hinge" stiffness="10" />
                                                    <body name="link_9" pos="0.05 0 0">
                                                        <geom fromto="0 0 0 0.05 0 0" size="0.035" type="capsule" rgba="0.1 0 1 1" />
                                                        <joint axis="0 0 1" class="link" name="joint_9" pos="0 0 0" range="-40.5 40.5" type="hinge" stiffness="10" />
                                                        <body name="link_10" pos="0.05 0 0">
                                                            <geom fromto="0 0 0 0.05 0 0" size="0.035" type="capsule" rgba="0.4 0.1 1 1" />
                                                            <joint axis="0 0 1" class="link" name="joint_10" pos="0 0 0" range="-40.5 40.5" type="hinge" stiffness="10" />
                                                            <body name="link_11" pos="0.05 0 0">
                                                                <geom fromto="0 0 0 0.05 0 0" size="0.035" type="capsule" rgba="0.1 0 1 1" />
                                                                <joint axis="0 0 1" class="link" name="joint_11" pos="0 0 0" range="-40.5 40.5" type="hinge" stiffness="10" />
                                                                <body name="link_12" pos="0.05 0 0">
                                                                    <geom fromto="0 0 0 0.05 0 0" size="0.035" type="capsule" rgba="0.4 0.1 1 1" />
                                                                    <joint axis="0 0 1" class="link" name="joint_12" pos="0 0 0" range="-40.5 40.5" type="hinge" stiffness="10" />
                                                                    <body name="link_13" pos="0.05 0 0">
                                                                        <geom fromto="0 0 0 0.05 0 0" size="0.035" type="capsule" rgba="0.1 0 1 1" />
                                                                        <joint axis="0 0 1" class="link" name="joint_13" pos="0 0 0" range="-40.5 40.5" type="hinge" stiffness="10" />
                                                                        <body name="link_14" pos="0.05 0 0">
                                                                            <geom fromto="0 0 0 0.05 0 0" size="0.035" type="capsule" rgba="0.4 0.1 1 1" />
                                                                            <joint axis="0 0 1" class="link" name="joint_14" pos="0 0 0" range="-40.5 40.5" type="hinge" stiffness="10" />
                                                                            <body name="link_15" pos="0.05 0 0">
                                                                                <geom fromto="0 0 0 0.05 0 0" size="0.035" type="capsule" rgba="0.1 0 1 1" />
                                                                                <joint axis="0 0 1" class="link" name="joint_15" pos="0 0 0" range="-40.5 40.5" type="hinge" stiffness="10" />
                                                                                <body name="link_16" pos="0.05 0 0">
                                                                                    <geom fromto="0 0 0 0.05 0 0" size="0.035" type="capsule" rgba="0.4 0.1 1 1" />
                                                                                    <joint axis="0 0 1" class="link" name="joint_16" pos="0 0 0" range="-40.5 40.5" type="hinge" stiffness="10" />
                                                                                    <body name="link_17" pos="0.05 0 0">
                                                                                        <geom fromto="0 0 0 0.05 0 0" size="0.035" type="capsule" rgba="0.1 0 1 1" />
                                                                                        <joint axis="0 0 1" class="link" name="joint_17" pos="0 0 0" range="-40.5 40.5" type="hinge" stiffness="10" />
                                                                                        <body name="link_18" pos="0.05 0 0">
                                                                                            <geom fromto="0 0 0 0.05 0 0" size="0.035" type="capsule" rgba="0.4 0.1 1 1" />
                                                                                            <joint axis="0 0 1" class="link" name="joint_18" pos="0 0 0" range="-40.5 40.5" type="hinge" stiffness="10" />
                                                                                            <body name="link_19" pos="0.05 0 0">
                                                                                                <geom fromto="0 0 0 0.05 0 0" size="0.035" type="capsule" rgba="0.1 0 1 1" />
                                                                                                <joint axis="0 0 1" class="link" name="joint_19" pos="0 0 0" range="-40.5 40.5" type="hinge" stiffness="10" />
                                                                                                <body name="link_20" pos="0.05 0 0">
                                                                                                    <geom fromto="0 0 0 0.05 0 0" size="0.035" type="capsule" rgba="0.4 0.1 1 1" />
                                                                                                    <joint axis="0 0 1" class="link" name="joint_20" pos="0 0 0" range="-40.5 40.5" type="hinge" stiffness="10" />
                                                                                                    <body name="link_21" pos="0.05 0 0">
                                                                                                        <geom fromto="0 0 0 0.05 0 0" size="0.035" type="capsule" rgba="0.1 0 1 1" />
                                                                                                        <joint axis="0 0 1" class="link" name="joint_21" pos="0 0 0" range="-40.5 40.5" type="hinge" stiffness="10" />
                                                                                                        <body name="link_22" pos="0.05 0 0">
                                                                                                            <geom fromto="0 0 0 0.05 0 0" size="0.035" type="capsule" rgba="0.4 0.1 1 1" />
                                                                                                            <joint axis="0 0 1" class="link" name="joint_22" pos="0 0 0" range="-40.5 40.5" type="hinge" stiffness="10" />
                                                                                                            <body name="link_23" pos="0.05 0 0">
                                                                                                                <geom fromto="0 0 0 0.05 0 0" size="0.035" type="capsule" rgba="0.1 0 1 1" />
                                                                                                                <joint axis="0 0 1" class="link" name="joint_23" pos="0 0 0" range="-40.5 40.5" type="hinge" stiffness="10" />
                                                                                                                <body name="link_24" pos="0.05 0 0">
                                                                                                                    <geom fromto="0 0 0 0.05 0 0" size="0.035" type="capsule" rgba="0.4 0.1 1 1" />
                                                                                                                    <joint axis="0 0 1" class="link" name="joint_24" pos="0 0 0" range="-40.5 40.5" type="hinge" stiffness="10" />
                                                                                                                    <body name="link_25" pos="0.05 0 0">
                                                                                                                        <geom fromto="0 0 0 0.05 0 0" size="0.035" type="capsule" rgba="0.1 0 1 1" />
                                                                                                                        <joint axis="0 0 1" class="link" name="joint_25" pos="0 0 0" range="-40.5 40.5" type="hinge" stiffness="10" />
                                                                                                                        <body name="link_26" pos="0.05 0 0">
                                                                                                                            <geom fromto="0 0 0 0.05 0 0" size="0.035" type="capsule" rgba="0.4 0.1 1 1" />
                                                                                                                            <joint axis="0 0 1" class="link" name="joint_26" pos="0 0 0" range="-40.5 40.5" type="hinge" stiffness="10" />
                                                                                                                            <body name="link_27" pos="0.05 0 0">
                                                                                                                                <geom fromto="0 0 0 0.05 0 0" size="0.035" type="capsule" rgba="0.1 0 1 1" />
                                                                                                                                <joint axis="0 0 1" class="link" name="joint_27" pos="0 0 0" range="-40.5 40.5" type="hinge" stiffness="10" />
                                                                                                                                <body name="link_28" pos="0.05 0 0">
                                                                                                                                    <geom fromto="0 0 0 0.05 0 0" size="0.035" type="capsule" rgba="0.4 0.1 1 1" />
                                                                                                                                    <joint axis="0 0 1" class="link" name="joint_28" pos="0 0 0" range="-40.5 40.5" type="hinge" stiffness="10" />
                                                                                                                                    <body name="link_29" pos="0.05 0 0">
                                                                                                                                        <geom fromto="0 0 0 0.05 0 0" size="0.035" type="capsule" rgba="0.1 0 1 1" />
                                                                                                                                        <joint axis="0 0 1" class="link" name="joint_29" pos="0 0 0" range="-40.5 40.5" type="hinge" stiffness="10" />
                                                                                                                                    </body>
                                                                                                                                </body>
                                                                                                                            </body>
                                                                                                                        </body>
                                                                                                                    </body>
                                                                                                                </body>
                                                                                                            </body>
                                                                                                        </body>
                                                                                                    </body>
                                                                                                </body>
                                                                                            </body>
                                                                                        </body>
                                                                                    </body>
                                                                                </body>
                                                                            </body>
                                                                        </body>
                                                                    </body>
                                                                </body>
                                                            </body>
                                                        </body>
                                                    </body>
                                                </body>
                                            </body>
                                        </body>
                                    </body>
                                </body>
                            </body>
                        </body>
                    </body>
                </body>
            </body>
        </body>
    </worldbody>
    <!--
		-->
    <actuator>
        <velocity ctrlrange="-2 2" joint="sphere_position" name="sphere_position" />
        <motor class="position" ctrlrange="-40.5 40.5" joint="base_joint" name="act_base_joint" />
        <motor class="position" ctrlrange="-40.5 40.5" joint="joint_0" name="act_joint_0" />
        <motor class="position" ctrlrange="-40.5 40.5" joint="joint_1" name="act_joint_1" />
        <motor class="position" ctrlrange="-40.5 40.5" joint="joint_2" name="act_joint_2" />
        <motor class="position" ctrlrange="-40.5 40.5" joint="joint_3" name="act_joint_3" />
        <motor class="position" ctrlrange="-40.5 40.5" joint="joint_4" name="act_joint_4" />
        <motor class="position" ctrlrange="-40.5 40.5" joint="joint_5" name="act_joint_5" />
        <motor class="position" ctrlrange="-40.5 40.5" joint="joint_6" name="act_joint_6" />
        <motor class="position" ctrlrange="-40.5 40.5" joint="joint_7" name="act_joint_7" />
        <motor class="position" ctrlrange="-40.5 40.5" joint="joint_8" name="act_joint_8" />
        <motor class="position" ctrlrange="-40.5 40.5" joint="joint_9" name="act_joint_9" />
        <motor class="position" ctrlrange="-40.5 40.5" joint="joint_10" name="act_joint_10" />
        <motor class="position" ctrlrange="-40.5 40.5" joint="joint_11" name="act_joint_11" />
        <motor class="position" ctrlrange="-40.5 40.5" joint="joint_12" name="act_joint_12" />
        <motor class="position" ctrlrange="-40.5 40.5" joint="joint_13" name="act_joint_13" />
        <motor class="position" ctrlrange="-40.5 40.5" joint="joint_14" name="act_joint_14" />
        <motor class="position" ctrlrange="-40.5 40.5" joint="joint_15" name="act_joint_15" />
        <motor class="position" ctrlrange="-40.5 40.5" joint="joint_16" name="act_joint_16" />
        <motor class="position" ctrlrange="-40.5 40.5" joint="joint_17" name="act_joint_17" />
        <motor class="position" ctrlrange="-40.5 40.5" joint="joint_18" name="act_joint_18" />
        <motor class="position" ctrlrange="-40.5 40.5" joint="joint_19" name="act_joint_19" />
        <motor class="position" ctrlrange="-40.5 40.5" joint="joint_20" name="act_joint_20" />
        <motor class="position" ctrlrange="-40.5 40.5" joint="joint_21" name="act_joint_21" />
        <motor class="position" ctrlrange="-40.5 40.5" joint="joint_22" name="act_joint_22" />
        <motor class="position" ctrlrange="-40.5 40.5" joint="joint_23" name="act_joint_23" />
        <motor class="position" ctrlrange="-40.5 40.5" joint="joint_24" name="act_joint_24" />
        <motor class="position" ctrlrange="-40.5 40.5" joint="joint_25" name="act_joint_25" />
        <motor class="position" ctrlrange="-40.5 40.5" joint="joint_26" name="act_joint_26" />
        <motor class="position" ctrlrange="-40.5 40.5" joint="joint_27" name="act_joint_27" />
        <motor class="position" ctrlrange="-40.5 40.5" joint="joint_28" name="act_joint_28" />
        <motor class="position" ctrlrange="-40.5 40.5" joint="joint_29" name="act_joint_29" />
    </actuator>
    <asset>
        <texture name="grid" type="2d" builtin="checker" width="512" height="512" rgb1=".1 .2 .3" rgb2=".2 .3 .4" />
        <material name="grid" texture="grid" texrepeat="1 1" texuniform="true" reflectance=".2" />
    </asset>
    <option gravity="0 0 -1.8" />
</mujoco>