<mujoco>
    <!-- === Configuration parameter stuff, default values === -->
    <default>
        <default class="position">
            <position ctrllimited="true" forcelimited="false" />
        </default>
        <default class="geom0">
            <geom conaffinity="0" contype="1" friction="1 0.005 0.001" margin="0.001" rgba="0.75 0.6 0.5 1" solimp="0.95 0.95 0.01" solref="0.008 1" />
        </default>
        <default class="link">
            <joint armature="0.1" damping="5" limited="true" stiffness="0" />
        </default>
    </default>
    <!-- === Physical robot definitions === -->
    <worldbody>
        <light diffuse=".5 .5 .5" pos="0 0 3" dir="0 0 -1" />
        <geom type="plane" size="100 100 0.1" rgba="0.46 0.86 1 1" />
        <!--
		-->
    <body name="base" pos="0 0 0.5">
            <joint type="free" damping="0.9" stiffness="1.2" />
            <geom size="0.05" type="sphere" />
            <body name="base_link" pos="0.05 0 0">
                <geom class="geom0" fromto="0 0 0 0.05 0 0" size="0.035" type="capsule" />
                <joint axis="0 0 1" class="link" name="base_joint" pos="0 0 0" range="-20.5 20.5" type="hinge" />
                <body name="link_0" pos="0.05 0 0">
                    <geom class="geom0" fromto="0 0 0 0.05 0 0" size="0.035" type="capsule" />
                    <joint axis="0 0 1" class="link" name="joint_0" pos="0 0 0" range="-20.5 20.5" type="hinge" />
                    <body name="link_1" pos="0.05 0 0">
                        <geom class="geom0" fromto="0 0 0 0.05 0 0" size="0.035" type="capsule" />
                        <joint axis="0 0 1" class="link" name="joint_1" pos="0 0 0" range="-20.5 20.5" type="hinge" />
                        <body name="link_2" pos="0.05 0 0">
                            <geom class="geom0" fromto="0 0 0 0.05 0 0" size="0.035" type="capsule" />
                            <joint axis="0 0 1" class="link" name="joint_2" pos="0 0 0" range="-20.5 20.5" type="hinge" />
                            <body name="link_3" pos="0.05 0 0">
                                <geom class="geom0" fromto="0 0 0 0.05 0 0" size="0.035" type="capsule" />
                                <joint axis="0 0 1" class="link" name="joint_3" pos="0 0 0" range="-20.5 20.5" type="hinge" />
                                <body name="link_4" pos="0.05 0 0">
                                    <geom class="geom0" fromto="0 0 0 0.05 0 0" size="0.035" type="capsule" />
                                    <joint axis="0 0 1" class="link" name="joint_4" pos="0 0 0" range="-20.5 20.5" type="hinge" />
                                    <body name="link_5" pos="0.05 0 0">
                                        <geom class="geom0" fromto="0 0 0 0.05 0 0" size="0.035" type="capsule" />
                                        <joint axis="0 0 1" class="link" name="joint_5" pos="0 0 0" range="-20.5 20.5" type="hinge" />
                                        <body name="link_6" pos="0.05 0 0">
                                            <geom class="geom0" fromto="0 0 0 0.05 0 0" size="0.035" type="capsule" />
                                            <joint axis="0 0 1" class="link" name="joint_6" pos="0 0 0" range="-20.5 20.5" type="hinge" />
                                            <body name="link_7" pos="0.05 0 0">
                                                <geom class="geom0" fromto="0 0 0 0.05 0 0" size="0.035" type="capsule" />
                                                <joint axis="0 0 1" class="link" name="joint_7" pos="0 0 0" range="-20.5 20.5" type="hinge" />
                                                <body name="link_8" pos="0.05 0 0">
                                                    <geom class="geom0" fromto="0 0 0 0.05 0 0" size="0.035" type="capsule" />
                                                    <joint axis="0 0 1" class="link" name="joint_8" pos="0 0 0" range="-20.5 20.5" type="hinge" />
                                                    <body name="link_9" pos="0.05 0 0">
                                                        <geom class="geom0" fromto="0 0 0 0.05 0 0" size="0.035" type="capsule" />
                                                        <joint axis="0 0 1" class="link" name="joint_9" pos="0 0 0" range="-20.5 20.5" type="hinge" />
                                                        <body name="link_10" pos="0.05 0 0">
                                                            <geom class="geom0" fromto="0 0 0 0.05 0 0" size="0.035" type="capsule" />
                                                            <joint axis="0 0 1" class="link" name="joint_10" pos="0 0 0" range="-20.5 20.5" type="hinge" />
                                                            <body name="link_11" pos="0.05 0 0">
                                                                <geom class="geom0" fromto="0 0 0 0.05 0 0" size="0.035" type="capsule" />
                                                                <joint axis="0 0 1" class="link" name="joint_11" pos="0 0 0" range="-20.5 20.5" type="hinge" />
                                                                <body name="link_12" pos="0.05 0 0">
                                                                    <geom class="geom0" fromto="0 0 0 0.05 0 0" size="0.035" type="capsule" />
                                                                    <joint axis="0 0 1" class="link" name="joint_12" pos="0 0 0" range="-20.5 20.5" type="hinge" />
                                                                    <body name="link_13" pos="0.05 0 0">
                                                                        <geom class="geom0" fromto="0 0 0 0.05 0 0" size="0.035" type="capsule" />
                                                                        <joint axis="0 0 1" class="link" name="joint_13" pos="0 0 0" range="-20.5 20.5" type="hinge" />
                                                                        <body name="link_14" pos="0.05 0 0">
                                                                            <geom class="geom0" fromto="0 0 0 0.05 0 0" size="0.035" type="capsule" />
                                                                            <joint axis="0 0 1" class="link" name="joint_14" pos="0 0 0" range="-20.5 20.5" type="hinge" />
                                                                            <body name="link_15" pos="0.05 0 0">
                                                                                <geom class="geom0" fromto="0 0 0 0.05 0 0" size="0.035" type="capsule" />
                                                                                <joint axis="0 0 1" class="link" name="joint_15" pos="0 0 0" range="-20.5 20.5" type="hinge" />
                                                                                <body name="link_16" pos="0.05 0 0">
                                                                                    <geom class="geom0" fromto="0 0 0 0.05 0 0" size="0.035" type="capsule" />
                                                                                    <joint axis="0 0 1" class="link" name="joint_16" pos="0 0 0" range="-20.5 20.5" type="hinge" />
                                                                                    <body name="link_17" pos="0.05 0 0">
                                                                                        <geom class="geom0" fromto="0 0 0 0.05 0 0" size="0.035" type="capsule" />
                                                                                        <joint axis="0 0 1" class="link" name="joint_17" pos="0 0 0" range="-20.5 20.5" type="hinge" />
                                                                                        <body name="link_18" pos="0.05 0 0">
                                                                                            <geom class="geom0" fromto="0 0 0 0.05 0 0" size="0.035" type="capsule" />
                                                                                            <joint axis="0 0 1" class="link" name="joint_18" pos="0 0 0" range="-20.5 20.5" type="hinge" />
                                                                                            <body name="link_19" pos="0.05 0 0">
                                                                                                <geom class="geom0" fromto="0 0 0 0.05 0 0" size="0.035" type="capsule" />
                                                                                                <joint axis="0 0 1" class="link" name="joint_19" pos="0 0 0" range="-20.5 20.5" type="hinge" />
                                                                                                <body name="link_20" pos="0.05 0 0">
                                                                                                    <geom class="geom0" fromto="0 0 0 0.05 0 0" size="0.035" type="capsule" />
                                                                                                    <joint axis="0 0 1" class="link" name="joint_20" pos="0 0 0" range="-20.5 20.5" type="hinge" />
                                                                                                    <body name="link_21" pos="0.05 0 0">
                                                                                                        <geom class="geom0" fromto="0 0 0 0.05 0 0" size="0.035" type="capsule" />
                                                                                                        <joint axis="0 0 1" class="link" name="joint_21" pos="0 0 0" range="-20.5 20.5" type="hinge" />
                                                                                                        <body name="link_22" pos="0.05 0 0">
                                                                                                            <geom class="geom0" fromto="0 0 0 0.05 0 0" size="0.035" type="capsule" />
                                                                                                            <joint axis="0 0 1" class="link" name="joint_22" pos="0 0 0" range="-20.5 20.5" type="hinge" />
                                                                                                            <body name="link_23" pos="0.05 0 0">
                                                                                                                <geom class="geom0" fromto="0 0 0 0.05 0 0" size="0.035" type="capsule" />
                                                                                                                <joint axis="0 0 1" class="link" name="joint_23" pos="0 0 0" range="-20.5 20.5" type="hinge" />
                                                                                                                <body name="link_24" pos="0.05 0 0">
                                                                                                                    <geom class="geom0" fromto="0 0 0 0.05 0 0" size="0.035" type="capsule" />
                                                                                                                    <joint axis="0 0 1" class="link" name="joint_24" pos="0 0 0" range="-20.5 20.5" type="hinge" />
                                                                                                                    <body name="link_25" pos="0.05 0 0">
                                                                                                                        <geom class="geom0" fromto="0 0 0 0.05 0 0" size="0.035" type="capsule" />
                                                                                                                        <joint axis="0 0 1" class="link" name="joint_25" pos="0 0 0" range="-20.5 20.5" type="hinge" />
                                                                                                                        <body name="link_26" pos="0.05 0 0">
                                                                                                                            <geom class="geom0" fromto="0 0 0 0.05 0 0" size="0.035" type="capsule" />
                                                                                                                            <joint axis="0 0 1" class="link" name="joint_26" pos="0 0 0" range="-20.5 20.5" type="hinge" />
                                                                                                                            <body name="link_27" pos="0.05 0 0">
                                                                                                                                <geom class="geom0" fromto="0 0 0 0.05 0 0" size="0.035" type="capsule" />
                                                                                                                                <joint axis="0 0 1" class="link" name="joint_27" pos="0 0 0" range="-20.5 20.5" type="hinge" />
                                                                                                                                <body name="link_28" pos="0.05 0 0">
                                                                                                                                    <geom class="geom0" fromto="0 0 0 0.05 0 0" size="0.035" type="capsule" />
                                                                                                                                    <joint axis="0 0 1" class="link" name="joint_28" pos="0 0 0" range="-20.5 20.5" type="hinge" />
                                                                                                                                    <body name="link_29" pos="0.05 0 0">
                                                                                                                                        <geom class="geom0" fromto="0 0 0 0.05 0 0" size="0.035" type="capsule" />
                                                                                                                                        <joint axis="0 0 1" class="link" name="joint_29" pos="0 0 0" range="-20.5 20.5" type="hinge" />
                                                                                                                                    </body>
                                                                                                                                </body>
                                                                                                                            </body>
                                                                                                                        </body>
                                                                                                                    </body>
                                                                                                                </body>
                                                                                                            </body>
                                                                                                        </body>
                                                                                                    </body>
                                                                                                </body>
                                                                                            </body>
                                                                                        </body>
                                                                                    </body>
                                                                                </body>
                                                                            </body>
                                                                        </body>
                                                                    </body>
                                                                </body>
                                                            </body>
                                                        </body>
                                                    </body>
                                                </body>
                                            </body>
                                        </body>
                                    </body>
                                </body>
                            </body>
                        </body>
                    </body>
                </body>
            </body>
        </body>
    </worldbody>
    <!--
		-->
    <actuator>
        <position class="position" ctrlrange="-1 1" joint="base_joint" kp="100" name="act_base_joint" />
        <position class="position" ctrlrange="-1 1" joint="joint_0" kp="100" name="act_joint_0" />
        <position class="position" ctrlrange="-1 1" joint="joint_1" kp="100" name="act_joint_1" />
        <position class="position" ctrlrange="-1 1" joint="joint_2" kp="100" name="act_joint_2" />
        <position class="position" ctrlrange="-1 1" joint="joint_3" kp="100" name="act_joint_3" />
        <position class="position" ctrlrange="-1 1" joint="joint_4" kp="100" name="act_joint_4" />
        <position class="position" ctrlrange="-1 1" joint="joint_5" kp="100" name="act_joint_5" />
        <position class="position" ctrlrange="-1 1" joint="joint_6" kp="100" name="act_joint_6" />
        <position class="position" ctrlrange="-1 1" joint="joint_7" kp="100" name="act_joint_7" />
        <position class="position" ctrlrange="-1 1" joint="joint_8" kp="100" name="act_joint_8" />
        <position class="position" ctrlrange="-1 1" joint="joint_9" kp="100" name="act_joint_9" />
        <position class="position" ctrlrange="-1 1" joint="joint_10" kp="100" name="act_joint_10" />
        <position class="position" ctrlrange="-1 1" joint="joint_11" kp="100" name="act_joint_11" />
        <position class="position" ctrlrange="-1 1" joint="joint_12" kp="100" name="act_joint_12" />
        <position class="position" ctrlrange="-1 1" joint="joint_13" kp="100" name="act_joint_13" />
        <position class="position" ctrlrange="-1 1" joint="joint_14" kp="100" name="act_joint_14" />
        <position class="position" ctrlrange="-1 1" joint="joint_15" kp="100" name="act_joint_15" />
        <position class="position" ctrlrange="-1 1" joint="joint_16" kp="100" name="act_joint_16" />
        <position class="position" ctrlrange="-1 1" joint="joint_17" kp="100" name="act_joint_17" />
        <position class="position" ctrlrange="-1 1" joint="joint_18" kp="100" name="act_joint_18" />
        <position class="position" ctrlrange="-1 1" joint="joint_19" kp="100" name="act_joint_19" />
        <position class="position" ctrlrange="-1 1" joint="joint_20" kp="100" name="act_joint_20" />
        <position class="position" ctrlrange="-1 1" joint="joint_21" kp="100" name="act_joint_21" />
        <position class="position" ctrlrange="-1 1" joint="joint_22" kp="100" name="act_joint_22" />
        <position class="position" ctrlrange="-1 1" joint="joint_23" kp="100" name="act_joint_23" />
        <position class="position" ctrlrange="-1 1" joint="joint_24" kp="100" name="act_joint_24" />
        <position class="position" ctrlrange="-1 1" joint="joint_25" kp="100" name="act_joint_25" />
        <position class="position" ctrlrange="-1 1" joint="joint_26" kp="100" name="act_joint_26" />
        <position class="position" ctrlrange="-1 1" joint="joint_27" kp="100" name="act_joint_27" />
        <position class="position" ctrlrange="-1 1" joint="joint_28" kp="100" name="act_joint_28" />
        <position class="position" ctrlrange="-1 1" joint="joint_29" kp="100" name="act_joint_29" />
    </actuator>
    <option gravity="0 0 -1.8" />
</mujoco>